2024-11-27 06:33:31,046 - __main__ - INFO - Starting ML pipeline...
2024-11-27 06:33:31,047 - root - INFO - Created directory: artifacts
2024-11-27 06:33:31,047 - root - INFO - Created directory: artifacts/ingested_data
2024-11-27 06:33:31,047 - root - INFO - Created directory: artifacts/transformed_data
2024-11-27 06:33:31,047 - root - INFO - Created directory: artifacts/models
2024-11-27 06:33:31,047 - root - INFO - Created directory: logs
2024-11-27 06:33:31,048 - __main__ - INFO - Step 1: Data Ingestion
2024-11-27 06:33:31,049 - __main__ - ERROR - Error in ML pipeline: [Errno 2] No such file or directory: 'dataset/loan_approval_dataset.csv'
Traceback (most recent call last):
  File "src/main.py", line 67, in main
    X, y = data_ingestion.initiate_data_ingestion()
  File "/root/code/relaxy-ai-engineer-exam-question/src/data_ingestion.py", line 74, in initiate_data_ingestion
    raise e
  File "/root/code/relaxy-ai-engineer-exam-question/src/data_ingestion.py", line 47, in initiate_data_ingestion
    df = pd.read_csv(self.data_path)
  File "/root/code/relaxy-ai-engineer-exam-question/venv/lib/python3.8/site-packages/pandas/io/parsers/readers.py", line 912, in read_csv
    return _read(filepath_or_buffer, kwds)
  File "/root/code/relaxy-ai-engineer-exam-question/venv/lib/python3.8/site-packages/pandas/io/parsers/readers.py", line 577, in _read
    parser = TextFileReader(filepath_or_buffer, **kwds)
  File "/root/code/relaxy-ai-engineer-exam-question/venv/lib/python3.8/site-packages/pandas/io/parsers/readers.py", line 1407, in __init__
    self._engine = self._make_engine(f, self.engine)
  File "/root/code/relaxy-ai-engineer-exam-question/venv/lib/python3.8/site-packages/pandas/io/parsers/readers.py", line 1661, in _make_engine
    self.handles = get_handle(
  File "/root/code/relaxy-ai-engineer-exam-question/venv/lib/python3.8/site-packages/pandas/io/common.py", line 859, in get_handle
    handle = open(
FileNotFoundError: [Errno 2] No such file or directory: 'dataset/loan_approval_dataset.csv'
